[2023-06-16T13:16:00.328+0700] {taskinstance.py:1103} INFO - Dependencies all met for dep_context=non-requeueable deps ti=<TaskInstance: thethree_reqif_to_rst.update_index_rst manual__2023-06-16T06:15:22+00:00 [queued]>
[2023-06-16T13:16:00.337+0700] {taskinstance.py:1103} INFO - Dependencies all met for dep_context=requeueable deps ti=<TaskInstance: thethree_reqif_to_rst.update_index_rst manual__2023-06-16T06:15:22+00:00 [queued]>
[2023-06-16T13:16:00.337+0700] {taskinstance.py:1308} INFO - Starting attempt 1 of 0
[2023-06-16T13:16:00.355+0700] {taskinstance.py:1327} INFO - Executing <Task(PythonOperator): update_index_rst> on 2023-06-16 06:15:22+00:00
[2023-06-16T13:16:00.358+0700] {standard_task_runner.py:57} INFO - Started process 7654 to run task
[2023-06-16T13:16:00.365+0700] {standard_task_runner.py:84} INFO - Running: ['airflow', 'tasks', 'run', 'thethree_reqif_to_rst', 'update_index_rst', 'manual__2023-06-16T06:15:22+00:00', '--job-id', '337', '--raw', '--subdir', 'DAGS_FOLDER/mainflow.py', '--cfg-path', '/var/folders/v7/qsb_cvl92z92z6jf7g1jc0zr0000gn/T/tmputp39hja']
[2023-06-16T13:16:00.367+0700] {standard_task_runner.py:85} INFO - Job 337: Subtask update_index_rst
[2023-06-16T13:16:00.426+0700] {task_command.py:410} INFO - Running <TaskInstance: thethree_reqif_to_rst.update_index_rst manual__2023-06-16T06:15:22+00:00 [running]> on host macbook-pro.local
[2023-06-16T13:16:00.504+0700] {taskinstance.py:1545} INFO - Exporting env vars: AIRFLOW_CTX_DAG_OWNER='The Three' AIRFLOW_CTX_DAG_ID='thethree_reqif_to_rst' AIRFLOW_CTX_TASK_ID='update_index_rst' AIRFLOW_CTX_EXECUTION_DATE='2023-06-16T06:15:22+00:00' AIRFLOW_CTX_TRY_NUMBER='1' AIRFLOW_CTX_DAG_RUN_ID='manual__2023-06-16T06:15:22+00:00'
[2023-06-16T13:16:00.526+0700] {taskinstance.py:1824} ERROR - Task failed with exception
Traceback (most recent call last):
  File "/Library/Frameworks/Python.framework/Versions/3.11/lib/python3.11/site-packages/airflow/operators/python.py", line 181, in execute
    return_value = self.execute_callable()
                   ^^^^^^^^^^^^^^^^^^^^^^^
  File "/Library/Frameworks/Python.framework/Versions/3.11/lib/python3.11/site-packages/airflow/operators/python.py", line 198, in execute_callable
    return self.python_callable(*self.op_args, **self.op_kwargs)
           ^^^^^^^^^^^^^^^^^^^^^^^^^^^^^^^^^^^^^^^^^^^^^^^^^^^^^
  File "/Users/lap14202/.airflow/dags/mainflow.py", line 58, in update_index_rst_task
    module_type = json_data[config['module']['type']]
                  ~~~~~~~~~^^^^^^^^^^^^^^^^^^^^^^^^^^
TypeError: unhashable type: 'dict'
[2023-06-16T13:16:00.536+0700] {taskinstance.py:1345} INFO - Marking task as FAILED. dag_id=thethree_reqif_to_rst, task_id=update_index_rst, execution_date=20230616T061522, start_date=20230616T061600, end_date=20230616T061600
[2023-06-16T13:16:00.545+0700] {standard_task_runner.py:104} ERROR - Failed to execute job 337 for task update_index_rst (unhashable type: 'dict'; 7654)
[2023-06-16T13:16:00.594+0700] {local_task_job_runner.py:225} INFO - Task exited with return code 1
[2023-06-16T13:16:00.610+0700] {taskinstance.py:2651} INFO - 0 downstream tasks scheduled from follow-on schedule check
